<?xml version="1.0"?>
<robot name="my_robot">

  <!-- ================= MATERIALS ================= -->
  <material name="grey"><color rgba="0.7 0.7 0.7 1"/></material>
  <material name="green"><color rgba="0 0.6 0 1"/></material>
  <material name="white"><color rgba="1 1 1 1"/></material>

  <!-- ================= BASE ================= -->
  <link name="base_footprint"/>

  <link name="base_link">
    <visual>
      <origin xyz="0 0 0.1"/>
      <geometry><box size="0.6 0.4 0.2"/></geometry>
      <material name="green"/>
    </visual>
    <collision>
      <origin xyz="0 0 0.1"/>
      <geometry><box size="0.6 0.4 0.2"/></geometry>
    </collision>
    <inertial>
      <origin xyz="0 0 0.1"/>
      <mass value="5.0"/>
      <inertia ixx="0.2" iyy="0.2" izz="0.2"
               ixy="0" ixz="0" iyz="0"/>
    </inertial>
  </link>

  <!-- ================= LIDAR ================= -->
  <link name="lidar">
    <visual>
      <geometry><cylinder radius="0.05" length="0.05"/></geometry>
      <material name="white"/>
    </visual>
    <collision>
      <geometry><cylinder radius="0.05" length="0.05"/></geometry>
    </collision>
    <inertial>
      <mass value="0.5"/>
      <inertia ixx="0.01" iyy="0.01" izz="0.01"
               ixy="0" ixz="0" iyz="0"/>
    </inertial>
  </link>

  <!-- ================= DEPTH CAMERA LINK ================= -->
  <link name="depth_camera">
    <visual>
      <geometry><box size="0.05 0.05 0.05"/></geometry>
      <material name="white"/>
    </visual>
    <collision>
      <geometry><box size="0.05 0.05 0.05"/></geometry>
    </collision>
    <inertial>
      <mass value="0.3"/>
      <inertia ixx="0.005" iyy="0.005" izz="0.005"
               ixy="0" ixz="0" iyz="0"/>
    </inertial>
  </link>

  <!-- ================= WHEELS ================= -->
  <link name="left_wheel">
    <visual>
      <geometry><cylinder radius="0.1" length="0.05"/></geometry>
      <origin rpy="1.5708 0 0"/>
      <material name="grey"/>
    </visual>
    <collision>
      <geometry><cylinder radius="0.1" length="0.05"/></geometry>
      <origin rpy="1.5708 0 0"/>
    </collision>
    <inertial>
      <mass value="1.0"/>
      <inertia ixx="0.02" iyy="0.02" izz="0.02"
               ixy="0" ixz="0" iyz="0"/>
    </inertial>
  </link>

  <link name="right_wheel">
    <visual>
      <geometry><cylinder radius="0.1" length="0.05"/></geometry>
      <origin rpy="1.5708 0 0"/>
      <material name="grey"/>
    </visual>
    <collision>
      <geometry><cylinder radius="0.1" length="0.05"/></geometry>
      <origin rpy="1.5708 0 0"/>
    </collision>
    <inertial>
      <mass value="1.0"/>
      <inertia ixx="0.02" iyy="0.02" izz="0.02"
               ixy="0" ixz="0" iyz="0"/>
    </inertial>
  </link>

  <!-- ================= CASTER ================= -->
  <link name="caster_wheel">
    <visual>
      <geometry><sphere radius="0.05"/></geometry>
      <material name="grey"/>
    </visual>
    <collision>
      <geometry><sphere radius="0.05"/></geometry>
    </collision>
    <inertial>
      <mass value="0.5"/>
      <inertia ixx="0.01" iyy="0.01" izz="0.01"
               ixy="0" ixz="0" iyz="0"/>
    </inertial>
  </link>

  <!-- ================= JOINTS ================= -->
  <joint name="base_joint" type="fixed">
    <parent link="base_footprint"/>
    <child link="base_link"/>
  </joint>

  <joint name="lidar_joint" type="fixed">
    <parent link="base_link"/>
    <child link="lidar"/>
    <origin xyz="0 0 0.25"/>
  </joint>

  <joint name="depth_camera_joint" type="fixed">
    <parent link="base_link"/>
    <child link="depth_camera"/>
    <origin xyz="0.30 0 0.25"/>
  </joint>

  <joint name="left_wheel_joint" type="continuous">
    <parent link="base_link"/>
    <child link="left_wheel"/>
    <origin xyz="-0.15 0.20 0.05"/>
    <axis xyz="0 1 0"/>
  </joint>

  <joint name="right_wheel_joint" type="continuous">
    <parent link="base_link"/>
    <child link="right_wheel"/>
    <origin xyz="-0.15 -0.20 0.05"/>
    <axis xyz="0 1 0"/>
  </joint>

  <joint name="caster_joint" type="fixed">
    <parent link="base_link"/>
    <child link="caster_wheel"/>
    <origin xyz="0.20 0 0.02"/>
  </joint>

  <!-- ================= DIFF DRIVE ================= -->
  <gazebo>
    <plugin name="diff_drive" filename="libgazebo_ros_diff_drive.so">
      <left_joint>left_wheel_joint</left_joint>
      <right_joint>right_wheel_joint</right_joint>
      <wheel_separation>0.40</wheel_separation>
      <wheel_radius>0.1</wheel_radius>
      <wheel_diameter>0.2</wheel_diameter>
      <cmd_vel_topic>cmd_vel</cmd_vel_topic>
      <odom_topic>odom</odom_topic>
      <odom_frame>odom</odom_frame>
      <base_frame>base_link</base_frame>
      <publish_odom>true</publish_odom>
      <publish_tf>true</publish_tf>
      <update_rate>50</update_rate>
    </plugin>
  </gazebo>

  <!-- ================= IMU ================= -->
  <gazebo reference="base_link">
    <plugin name="imu_plugin" filename="libgazebo_ros_imu_sensor.so">
      <ros><remapping>~/out:=imu/data</remapping></ros>
      <update_rate>100</update_rate>
      <frame_name>base_link</frame_name>
    </plugin>
  </gazebo>

  <!-- ================= LIDAR SENSOR ================= -->
  <gazebo reference="lidar">
    <sensor name="lidar_sensor" type="ray">
      <update_rate>10</update_rate>
      <ray>
        <scan>
          <horizontal>
            <samples>360</samples>
            <min_angle>-3.14159</min_angle>
            <max_angle>3.14159</max_angle>
          </horizontal>
        </scan>
        <range>
          <min>0.12</min>
          <max>10.0</max>
          <resolution>0.01</resolution>
        </range>
      </ray>
      <plugin name="lidar_plugin" filename="libgazebo_ros_ray_sensor.so">
        <topic_name>scan</topic_name>
        <frame_name>lidar</frame_name>
        <output_type>sensor_msgs/LaserScan</output_type>
      </plugin>
    </sensor>
  </gazebo>

  <!-- ================= GPS ================= -->
  <gazebo reference="base_link">
    <sensor name="gps_sensor" type="gps">
      <update_rate>5</update_rate>
      <plugin name="gps_plugin" filename="libgazebo_ros_gps_sensor.so">
        <topic_name>fix</topic_name>
        <frame_name>base_link</frame_name>
      </plugin>
    </sensor>
  </gazebo>

  <!-- ================= DEPTH CAMERA SENSOR (FIXED) ================= -->
  <gazebo reference="depth_camera">
    <sensor name="camera_sensor" type="camera">
      <update_rate>30</update_rate>
      <camera>
        <horizontal_fov>1.047</horizontal_fov>
        <image>
          <width>640</width>
          <height>480</height>
          <format>R8G8B8</format>
        </image>
        <depth>true</depth>
        <clip>
          <near>0.1</near>
          <far>5.0</far>
        </clip>
      </camera>
      <plugin name="camera_plugin" filename="libgazebo_ros_camera.so">
        <camera_name>camera</camera_name>
        <frame_name>depth_camera</frame_name>
        <image_topic_name>image_raw</image_topic_name>
        <camera_info_topic_name>camera_info</camera_info_topic_name>
        <depth_image_topic_name>depth/image_raw</depth_image_topic_name>
        <point_cloud_topic_name>points</point_cloud_topic_name>
      </plugin>
    </sensor>
  </gazebo>

</robot>

