<?xml version="1.0"?>
<robot name="my_robot">

  <!-- ================= MATERIALS ================= -->
  <material name="grey"><color rgba="0.7 0.7 0.7 1"/></material>
  <material name="green"><color rgba="0 0.6 0 1"/></material>
  <material name="white"><color rgba="1 1 1 1"/></material>
  <material name="black"><color rgba="0 0 0 1"/></material>

  <!-- ================= BASE ================= -->
  <link name="base_footprint"/>

  <link name="base_link">
    <visual>
      <origin xyz="0 0 0.1"/>
      <geometry><box size="0.6 0.4 0.2"/></geometry>
      <material name="green"/>
    </visual>
    <collision>
      <origin xyz="0 0 0.1"/>
      <geometry><box size="0.6 0.4 0.2"/></geometry>
    </collision>
    <inertial>
      <origin xyz="0 0 0.1"/>
      <mass value="5.0"/>
      <inertia ixx="0.2" iyy="0.2" izz="0.2"
               ixy="0" ixz="0" iyz="0"/>
    </inertial>
  </link>

  <joint name="base_joint" type="fixed">
    <parent link="base_footprint"/>
    <child link="base_link"/>
  </joint>

  <!-- ================= WHEELS (REFERENCE STYLE) ================= -->
  <link name="left_wheel">
    <visual>
      <geometry><cylinder radius="0.1" length="0.05"/></geometry>
      <origin rpy="1.5708 0 0"/>
      <material name="grey"/>
    </visual>
    <collision>
      <geometry><cylinder radius="0.1" length="0.05"/></geometry>
      <origin rpy="1.5708 0 0"/>
    </collision>
    <inertial>
      <mass value="1.0"/>
      <inertia ixx="0.02" iyy="0.02" izz="0.02"
               ixy="0" ixz="0" iyz="0"/>
    </inertial>
  </link>

  <joint name="left_wheel_joint" type="continuous">
    <parent link="base_link"/>
    <child link="left_wheel"/>
    <origin xyz="-0.15 0.20 0.05"/>
    <axis xyz="0 1 0"/>
  </joint>

  <link name="right_wheel">
    <visual>
      <geometry><cylinder radius="0.1" length="0.05"/></geometry>
      <origin rpy="1.5708 0 0"/>
      <material name="grey"/>
    </visual>
    <collision>
      <geometry><cylinder radius="0.1" length="0.05"/></geometry>
      <origin rpy="1.5708 0 0"/>
    </collision>
    <inertial>
      <mass value="1.0"/>
      <inertia ixx="0.02" iyy="0.02" izz="0.02"
               ixy="0" ixz="0" iyz="0"/>
    </inertial>
  </link>

  <joint name="right_wheel_joint" type="continuous">
    <parent link="base_link"/>
    <child link="right_wheel"/>
    <origin xyz="-0.15 -0.20 0.05"/>
    <axis xyz="0 1 0"/>
  </joint>

  <!-- ================= CASTER ================= -->
  <link name="caster_wheel">
    <visual><geometry><sphere radius="0.05"/></geometry></visual>
    <collision><geometry><sphere radius="0.05"/></geometry></collision>
    <inertial>
      <mass value="0.5"/>
      <inertia ixx="0.01" iyy="0.01" izz="0.01"
               ixy="0" ixz="0" iyz="0"/>
    </inertial>
  </link>

  <joint name="caster_joint" type="fixed">
    <parent link="base_link"/>
    <child link="caster_wheel"/>
    <origin xyz="0.20 0 0.02"/>
  </joint>

  <!-- ================= LIDAR ================= -->
  <link name="lidar_link">
    <visual><geometry><cylinder radius="0.05" length="0.05"/></geometry></visual>
  </link>

  <joint name="lidar_joint" type="fixed">
    <parent link="base_link"/>
    <child link="lidar_link"/>
    <origin xyz="0 0 0.25"/>
  </joint>

<gazebo reference="lidar_link">
  <sensor name="lidar" type="ray">
    <update_rate>10</update_rate>
    <ray>
      <scan>
        <horizontal>
          <samples>360</samples>
          <min_angle>-3.14159</min_angle>
          <max_angle>3.14159</max_angle>
        </horizontal>
      </scan>
      <range>
        <min>0.12</min>
        <max>10.0</max>
      </range>
    </ray>

    <plugin name="gazebo_ros_laser" filename="libgazebo_ros_ray_sensor.so">
      <!-- THIS MUST BE EXACT -->
      <topic_name>scan</topic_name>
      <frame_name>lidar_link</frame_name>
      <output_type>sensor_msgs/LaserScan</output_type>
    </plugin>
  </sensor>
</gazebo>



  <!-- ================= DEPTH CAMERA ================= -->
  <link name="depth_camera_link">
    <visual><geometry><box size="0.05 0.05 0.05"/></geometry></visual>
  </link>

  <joint name="depth_camera_joint" type="fixed">
    <parent link="base_link"/>
    <child link="depth_camera_link"/>
    <origin xyz="0.30 0 0.20"/>
  </joint>

  <gazebo reference="depth_camera_link">
    <sensor name="depth_camera" type="depth">
      <update_rate>30</update_rate>
      <camera>
        <horizontal_fov>1.047</horizontal_fov>
        <image><width>640</width><height>480</height><format>R8G8B8</format></image>
        <clip><near>0.1</near><far>5.0</far></clip>
      </camera>
      <plugin name="depth_camera_plugin" filename="libgazebo_ros_camera.so">
        <frame_name>depth_camera_link</frame_name>
        <image_topic_name>image_raw</image_topic_name>
        <depth_image_topic_name>depth/image_raw</depth_image_topic_name>
        <camera_info_topic_name>camera_info</camera_info_topic_name>
        <point_cloud_topic_name>points</point_cloud_topic_name>
      </plugin>
    </sensor>
  </gazebo>

  <!-- ================= IMU ================= -->
  <link name="imu_link"/>

  <joint name="imu_joint" type="fixed">
    <parent link="base_link"/>
    <child link="imu_link"/>
    <origin xyz="0 0 0.15"/>
  </joint>

  <gazebo reference="imu_link">
    <sensor name="imu" type="imu">
      <update_rate>100</update_rate>
      <plugin name="imu_plugin" filename="libgazebo_ros_imu_sensor.so">
        <topic_name>imu/data</topic_name>
        <frame_name>imu_link</frame_name>
      </plugin>
    </sensor>
  </gazebo>

  <!-- ================= DIFF DRIVE ================= -->
<gazebo>
  <plugin name="diff_drive" filename="libgazebo_ros_diff_drive.so">
    <left_joint>left_wheel_joint</left_joint>
    <right_joint>right_wheel_joint</right_joint>

    <wheel_separation>0.40</wheel_separation>
    <wheel_radius>0.1</wheel_radius>

    <cmd_vel_topic>cmd_vel</cmd_vel_topic>

    <!-- 🔴 REQUIRED -->
    <odom_topic>odom</odom_topic>
    <publish_odom>true</publish_odom>
    <publish_tf>true</publish_tf>

    <odom_frame>odom</odom_frame>
    <base_frame>base_link</base_frame>

    <update_rate>50</update_rate>
  </plugin>
</gazebo>

<!-- ================= JOINT STATE PUBLISHER ================= -->
<gazebo>
  <plugin name="joint_state_publisher"
          filename="libgazebo_ros_joint_state_publisher.so">
    <update_rate>50</update_rate>
    <joint_name>left_wheel_joint</joint_name>
    <joint_name>right_wheel_joint</joint_name>
  </plugin>
</gazebo>



</robot>

